Traceback (most recent call last):
  File "/Users/ashley/anaconda3/envs/jb/lib/python3.11/site-packages/jupyter_cache/executors/utils.py", line 58, in single_nb_execution
    executenb(
  File "/Users/ashley/anaconda3/envs/jb/lib/python3.11/site-packages/nbclient/client.py", line 1305, in execute
    return NotebookClient(nb=nb, resources=resources, km=km, **kwargs).execute()
           ^^^^^^^^^^^^^^^^^^^^^^^^^^^^^^^^^^^^^^^^^^^^^^^^^^^^^^^^^^^^^^^^^^^^^
  File "/Users/ashley/anaconda3/envs/jb/lib/python3.11/site-packages/jupyter_core/utils/__init__.py", line 166, in wrapped
    return loop.run_until_complete(inner)
           ^^^^^^^^^^^^^^^^^^^^^^^^^^^^^^
  File "/Users/ashley/anaconda3/envs/jb/lib/python3.11/asyncio/base_events.py", line 650, in run_until_complete
    return future.result()
           ^^^^^^^^^^^^^^^
  File "/Users/ashley/anaconda3/envs/jb/lib/python3.11/contextlib.py", line 222, in __aexit__
    await self.gen.athrow(typ, value, traceback)
  File "/Users/ashley/anaconda3/envs/jb/lib/python3.11/site-packages/nbclient/client.py", line 650, in async_setup_kernel
    yield
  File "/Users/ashley/anaconda3/envs/jb/lib/python3.11/site-packages/nbclient/client.py", line 705, in async_execute
    await self.async_execute_cell(
  File "/Users/ashley/anaconda3/envs/jb/lib/python3.11/site-packages/nbclient/client.py", line 1058, in async_execute_cell
    await self._check_raise_for_error(cell, cell_index, exec_reply)
  File "/Users/ashley/anaconda3/envs/jb/lib/python3.11/site-packages/nbclient/client.py", line 914, in _check_raise_for_error
    raise CellExecutionError.from_cell_and_msg(cell, exec_reply_content)
nbclient.exceptions.CellExecutionError: An error occurred while executing the following cell:
------------------
# Change the filename to EXACTLY match your file
filename = 'leech spontaneous .txt'

# Load & check shape of file
try:
    data = np.genfromtxt(filename, dtype=float, skip_header=6, delimiter='\t',encoding = 'unicode_escape')
except FileNotFoundError:
    print('Your file was not found. Please make sure you\'ve uploaded it following these directions: ')
    print('https://bipn145.github.io/intro.html#uploading-data-to-colab')
except ValueError:
    print('It looks like your data is the wrong shape, did you export the CURRENT SELECTION only?')

if data.shape[1] == 2:
    time, recording = data[:,0], data[:,1]
    print('Stored file with two columns as recording & time.')
elif data.shape[1] == 3:
    time, recording = data[:,0], data[:,1]
    recording_2 = data[:,2]
    print('Stored file with two columns as recording_1, recording_2, & time.')
else:
    print('Invalid data file. Please upload a .txt file exported from LabChart with one or two channels.')
------------------

----- stdout -----
Your file was not found. Please make sure you've uploaded it following these directions: 
https://bipn145.github.io/intro.html#uploading-data-to-colab
------------------

[0;31m---------------------------------------------------------------------------[0m
[0;31mNameError[0m                                 Traceback (most recent call last)
Cell [0;32mIn[2], line 13[0m
[1;32m     10[0m [38;5;28;01mexcept[39;00m [38;5;167;01mValueError[39;00m:
[1;32m     11[0m     [38;5;28mprint[39m([38;5;124m'[39m[38;5;124mIt looks like your data is the wrong shape, did you export the CURRENT SELECTION only?[39m[38;5;124m'[39m)
[0;32m---> 13[0m [38;5;28;01mif[39;00m [43mdata[49m[38;5;241m.[39mshape[[38;5;241m1[39m] [38;5;241m==[39m [38;5;241m2[39m:
[1;32m     14[0m     time, recording [38;5;241m=[39m data[:,[38;5;241m0[39m], data[:,[38;5;241m1[39m]
[1;32m     15[0m     [38;5;28mprint[39m([38;5;124m'[39m[38;5;124mStored file with two columns as recording & time.[39m[38;5;124m'[39m)

[0;31mNameError[0m: name 'data' is not defined

